Workbook

Sheet Comparação
A1: Comparação: modelo inicial x modelo melhorado (Q2: 2→3 servidores e capacidade 8→10)
A3: Fila | B3: Índice | C3: Inicial | D3: Melhorado | E3: Variação
A4: Q1 - Recepção/Triagem | B4: População N | C4: ='Modelo inicial'!B19 -> 0.76563076 | D4: ='Modelo melhorado'!B19 -> 0.76011562 | E4: =IF(C4=0,0,(D4-C4)/C4) -> -0.0072033988
A5: Q1 - Recepção/Triagem | B5: Vazão X (cl/min) | C5: ='Modelo inicial'!B20 -> 0.2505163 | D5: ='Modelo melhorado'!B20 -> 0.24928708 | E5: =IF(C5=0,0,(D5-C5)/C5) -> -0.0049067319
A6: Q1 - Recepção/Triagem | B6: Utilização U | C6: ='Modelo inicial'!B21 -> 0.7515489 | D6: ='Modelo melhorado'!B21 -> 0.74786125 | E6: =IF(C6=0,0,(D6-C6)/C6) -> -0.0049067319
A7: Q1 - Recepção/Triagem | B7: Tempo de resposta R (min) | C7: ='Modelo inicial'!B22 -> 3.0562113 | D7: ='Modelo melhorado'!B22 -> 3.0491576 | E7: =IF(C7=0,0,(D7-C7)/C7) -> -0.0023079916
A8: Q1 - Recepção/Triagem | B8: Perdas de clientes | C8: ='Modelo inicial'!B18 -> 0 | D8: ='Modelo melhorado'!B18 -> 0 | E8: =IF(C8=0,0,(D8-C8)/C8) -> 0
A9: Q2 - Bancada de reparo | B9: População N | C9: ='Modelo inicial'!B45 -> 7.1412941 | D9: ='Modelo melhorado'!B47 -> 4.6402858 | E9: =IF(C9=0,0,(D9-C9)/C9) -> -0.35021781
A10: Q2 - Bancada de reparo | B10: Vazão X (cl/min) | C10: ='Modelo inicial'!B46 -> 0.16663538 | D10: ='Modelo melhorado'!B48 -> 0.23264013 | E10: =IF(C10=0,0,(D10-C10)/C10) -> 0.39610279
A11: Q2 - Bancada de reparo | B11: Utilização U | C11: ='Modelo inicial'!B47 -> 0.99981231 | D11: ='Modelo melhorado'!B49 -> 0.9305605 | E11: =IF(C11=0,0,(D11-C11)/C11) -> -0.069264806
A12: Q2 - Bancada de reparo | B12: Tempo de resposta R (min) | C12: ='Modelo inicial'!B48 -> 42.855809 | D12: ='Modelo melhorado'!B50 -> 19.946197 | E12: =IF(C12=0,0,(D12-C12)/C12) -> -0.53457425
A13: Q2 - Bancada de reparo | B13: Perdas de clientes | C13: ='Modelo inicial'!B44 -> 4059 | D13: ='Modelo melhorado'!B46 -> 121 | E13: =IF(C13=0,0,(D13-C13)/C13) -> -0.9701897
A14: Q3 - Teste de qualidade | B14: População N | C14: ='Modelo inicial'!B69 -> 1.1165614 | D14: ='Modelo melhorado'!B71 -> 3.0290205 | E14: =IF(C14=0,0,(D14-C14)/C14) -> 1.7128113
A15: Q3 - Teste de qualidade | B15: Vazão X (cl/min) | C15: ='Modelo inicial'!B70 -> 0.18820025 | D15: ='Modelo melhorado'!B72 -> 0.24071498 | E15: =IF(C15=0,0,(D15-C15)/C15) -> 0.27903648
A16: Q3 - Teste de qualidade | B16: Utilização U | C16: ='Modelo inicial'!B71 -> 0.75280099 | D16: ='Modelo melhorado'!B73 -> 0.96285993 | E16: =IF(C16=0,0,(D16-C16)/C16) -> 0.27903648
A17: Q3 - Teste de qualidade | B17: Tempo de resposta R (min) | C17: ='Modelo inicial'!B72 -> 5.9328372 | D17: ='Modelo melhorado'!B74 -> 12.583432 | E17: =IF(C17=0,0,(D17-C17)/C17) -> 1.1209804
A18: Q3 - Teste de qualidade | B18: Perdas de clientes | C18: ='Modelo inicial'!B68 -> 0 | D18: ='Modelo melhorado'!B70 -> 331 | E18: =IF(C18=0,0,(D18-C18)/C18) -> 0
A19: Tempo global da simulação | C19: ='Modelo inicial'!B3 -> 68449.704 | D19: ='Modelo melhorado'!B3 -> 58884.026
A21: Verde = valores vindos das outras abas. Mesma semente (1) e 100.000 aleatórios nos dois cenários.

Sheet Modelo inicial
A1: Índices de desempenho - Modelo inicial (semente 1, 100.000 aleatórios)
A2: Células em azul = dados vindos do simulador (resultado_*.txt). Demais células = fórmulas (M9: N=Σn·π; X=Σmin(n,c)·μ·π; U=Σmin(n,c)·π/c; R=N/X; μ=1/tempo médio de atendimento).
A3: Tempo global da simulação | B3: 68449.704
A5: Q1 - Recepção/Triagem
A6: Servidores (c) | B6: 1
A7: Capacidade (K) | B7: 10
A8: Atend. mínimo | B8: 2
A9: Atend. máximo | B9: 4
A10: Tempo médio de atendimento | B10: =($B$8+$B$9)/2 -> 3
A11: Taxa de atendimento μ = 1/tempo médio | B11: =1/B10 -> 0.33333333
A13: Estado n | B13: Tempo acumulado | C13: π(n) | D13: min(n,c) | E13: n·π(n) | F13: min(n,c)·π(n)
A14: 0 | B14: 17006.404 | C14: =B14/SUM($B$14:$B$16) -> 0.2484511 | D14: =MIN(A14,$B$6) -> 0 | E14: =A14*C14 -> 0 | F14: =D14*C14 -> 0
A15: 1 | B15: 50479.401 | C15: =B15/SUM($B$14:$B$16) -> 0.73746704 | D15: =MIN(A15,$B$6) -> 1 | E15: =A15*C15 -> 0.73746704 | F15: =D15*C15 -> 0.73746704
A16: 2 | B16: 963.89899 | C16: =B16/SUM($B$14:$B$16) -> 0.014081858 | D16: =MIN(A16,$B$6) -> 1 | E16: =A16*C16 -> 0.028163715 | F16: =D16*C16 -> 0.014081858
A17: Total | B17: =SUM(B14:B16) -> 68449.704 | C17: =SUM(C14:C16) -> 1
A18: Perdas de clientes | B18: 0
A19: População média N | B19: =SUM(E14:E16) -> 0.76563076
A20: Vazão X (clientes/min) | B20: =B11*SUM(F14:F16) -> 0.2505163
A21: Utilização U | B21: =SUM(F14:F16)/$B$6 -> 0.7515489
A22: Tempo de resposta R = N/X (min) | B22: =B19/B20 -> 3.0562113
A25: Q2 - Bancada de reparo
A26: Servidores (c) | B26: 2
A27: Capacidade (K) | B27: 8
A28: Atend. mínimo | B28: 8
A29: Atend. máximo | B29: 16
A30: Tempo médio de atendimento | B30: =($B$28+$B$29)/2 -> 12
A31: Taxa de atendimento μ = 1/tempo médio | B31: =1/B30 -> 0.083333333
A33: Estado n | B33: Tempo acumulado | C33: π(n) | D33: min(n,c) | E33: n·π(n) | F33: min(n,c)·π(n)
A34: 0 | B34: 9.3642084 | C34: =B34/SUM($B$34:$B$42) -> 0.00013680422 | D34: =MIN(A34,$B$26) -> 0 | E34: =A34*C34 -> 0 | F34: =D34*C34 -> 0
A35: 1 | B35: 6.9667268 | C35: =B35/SUM($B$34:$B$42) -> 0.00010177877 | D35: =MIN(A35,$B$26) -> 1 | E35: =A35*C35 -> 0.00010177877 | F35: =D35*C35 -> 0.00010177877
A36: 2 | B36: 11.475544 | C36: =B36/SUM($B$34:$B$42) -> 0.00016764929 | D36: =MIN(A36,$B$26) -> 2 | E36: =A36*C36 -> 0.00033529857 | F36: =D36*C36 -> 0.00033529857
A37: 3 | B37: 66.029041 | C37: =B37/SUM($B$34:$B$42) -> 0.00096463588 | D37: =MIN(A37,$B$26) -> 2 | E37: =A37*C37 -> 0.0028939077 | F37: =D37*C37 -> 0.0019292718
A38: 4 | B38: 470.00204 | C38: =B38/SUM($B$34:$B$42) -> 0.0068663853 | D38: =MIN(A38,$B$26) -> 2 | E38: =A38*C38 -> 0.027465541 | F38: =D38*C38 -> 0.013732771
A39: 5 | B39: 2165.5002 | C39: =B39/SUM($B$34:$B$42) -> 0.031636371 | D39: =MIN(A39,$B$26) -> 2 | E39: =A39*C39 -> 0.15818185 | F39: =D39*C39 -> 0.063272741
A40: 6 | B40: 10955.182 | C40: =B40/SUM($B$34:$B$42) -> 0.16004717 | D40: =MIN(A40,$B$26) -> 2 | E40: =A40*C40 -> 0.96028303 | F40: =D40*C40 -> 0.32009434
A41: 7 | B41: 27968.612 | C41: =B41/SUM($B$34:$B$42) -> 0.40860092 | D41: =MIN(A41,$B$26) -> 2 | E41: =A41*C41 -> 2.8602064 | F41: =D41*C41 -> 0.81720184
A42: 8 | B42: 26796.573 | C42: =B42/SUM($B$34:$B$42) -> 0.39147828 | D42: =MIN(A42,$B$26) -> 2 | E42: =A42*C42 -> 3.1318263 | F42: =D42*C42 -> 0.78295657
A43: Total | B43: =SUM(B34:B42) -> 68449.704 | C43: =SUM(C34:C42) -> 1
A44: Perdas de clientes | B44: 4059
A45: População média N | B45: =SUM(E34:E42) -> 7.1412941
...

Sheet Modelo melhorado
A1: Índices de desempenho - Modelo melhorado (semente 1, 100.000 aleatórios)
A2: Células em azul = dados vindos do simulador (resultado_*.txt). Demais células = fórmulas (M9: N=Σn·π; X=Σmin(n,c)·μ·π; U=Σmin(n,c)·π/c; R=N/X; μ=1/tempo médio de atendimento).
A3: Tempo global da simulação | B3: 58884.026
A5: Q1 - Recepção/Triagem
A6: Servidores (c) | B6: 1
A7: Capacidade (K) | B7: 10
A8: Atend. mínimo | B8: 2
A9: Atend. máximo | B9: 4
A10: Tempo médio de atendimento | B10: =($B$8+$B$9)/2 -> 3
A11: Taxa de atendimento μ = 1/tempo médio | B11: =1/B10 -> 0.33333333
A13: Estado n | B13: Tempo acumulado | C13: π(n) | D13: min(n,c) | E13: n·π(n) | F13: min(n,c)·π(n)
A14: 0 | B14: 14846.945 | C14: =B14/SUM($B$14:$B$16) -> 0.25213875 | D14: =MIN(A14,$B$6) -> 0 | E14: =A14*C14 -> 0 | F14: =D14*C14 -> 0
A15: 1 | B15: 43315.495 | C15: =B15/SUM($B$14:$B$16) -> 0.73560689 | D15: =MIN(A15,$B$6) -> 1 | E15: =A15*C15 -> 0.73560689 | F15: =D15*C15 -> 0.73560689
A16: 2 | B16: 721.58623 | C16: =B16/SUM($B$14:$B$16) -> 0.012254363 | D16: =MIN(A16,$B$6) -> 1 | E16: =A16*C16 -> 0.024508726 | F16: =D16*C16 -> 0.012254363
A17: Total | B17: =SUM(B14:B16) -> 58884.026 | C17: =SUM(C14:C16) -> 1
A18: Perdas de clientes | B18: 0
A19: População média N | B19: =SUM(E14:E16) -> 0.76011562
A20: Vazão X (clientes/min) | B20: =B11*SUM(F14:F16) -> 0.24928708
A21: Utilização U | B21: =SUM(F14:F16)/$B$6 -> 0.74786125
A22: Tempo de resposta R = N/X (min) | B22: =B19/B20 -> 3.0491576
A25: Q2 - Bancada de reparo
A26: Servidores (c) | B26: 3
A27: Capacidade (K) | B27: 10
A28: Atend. mínimo | B28: 8
A29: Atend. máximo | B29: 16
A30: Tempo médio de atendimento | B30: =($B$28+$B$29)/2 -> 12
A31: Taxa de atendimento μ = 1/tempo médio | B31: =1/B30 -> 0.083333333
A33: Estado n | B33: Tempo acumulado | C33: π(n) | D33: min(n,c) | E33: n·π(n) | F33: min(n,c)·π(n)
A34: 0 | B34: 299.24426 | C34: =B34/SUM($B$34:$B$44) -> 0.005081926 | D34: =MIN(A34,$B$26) -> 0 | E34: =A34*C34 -> 0 | F34: =D34*C34 -> 0
A35: 1 | B35: 2222.8908 | C35: =B35/SUM($B$34:$B$44) -> 0.037750319 | D35: =MIN(A35,$B$26) -> 1 | E35: =A35*C35 -> 0.037750319 | F35: =D35*C35 -> 0.037750319
A36: 2 | B36: 6923.1174 | C36: =B36/SUM($B$34:$B$44) -> 0.11757208 | D36: =MIN(A36,$B$26) -> 2 | E36: =A36*C36 -> 0.23514416 | F36: =D36*C36 -> 0.23514416
A37: 3 | B37: 11120.14 | C37: =B37/SUM($B$34:$B$44) -> 0.18884817 | D37: =MIN(A37,$B$26) -> 3 | E37: =A37*C37 -> 0.5665445 | F37: =D37*C37 -> 0.5665445
A38: 4 | B38: 10747.905 | C38: =B38/SUM($B$34:$B$44) -> 0.18252666 | D38: =MIN(A38,$B$26) -> 3 | E38: =A38*C38 -> 0.73010665 | F38: =D38*C38 -> 0.54757999
A39: 5 | B39: 8581.9883 | C39: =B39/SUM($B$34:$B$44) -> 0.14574391 | D39: =MIN(A39,$B$26) -> 3 | E39: =A39*C39 -> 0.72871957 | F39: =D39*C39 -> 0.43723174
A40: 6 | B40: 6581.8236 | C40: =B40/SUM($B$34:$B$44) -> 0.11177605 | D40: =MIN(A40,$B$26) -> 3 | E40: =A40*C40 -> 0.67065628 | F40: =D40*C40 -> 0.33532814
A41: 7 | B41: 5197.7628 | C41: =B41/SUM($B$34:$B$44) -> 0.088271186 | D41: =MIN(A41,$B$26) -> 3 | E41: =A41*C41 -> 0.6178983 | F41: =D41*C41 -> 0.26481356
A42: 8 | B42: 3826.0626 | C42: =B42/SUM($B$34:$B$44) -> 0.06497624 | D42: =MIN(A42,$B$26) -> 3 | E42: =A42*C42 -> 0.51980992 | F42: =D42*C42 -> 0.19492872
A43: 9 | B43: 2407.0929 | C43: =B43/SUM($B$34:$B$44) -> 0.040878538 | D43: =MIN(A43,$B$26) -> 3 | E43: =A43*C43 -> 0.36790685 | F43: =D43*C43 -> 0.12263562
A44: 10 | B44: 975.99812 | C44: =B44/SUM($B$34:$B$44) -> 0.016574922 | D44: =MIN(A44,$B$26) -> 3 | E44: =A44*C44 -> 0.16574922 | F44: =D44*C44 -> 0.049724765
A45: Total | B45: =SUM(B34:B44) -> 58884.026 | C45: =SUM(C34:C44) -> 1
...
